<?xml version="1.0" ?>
<mujoco model="rollin_justin">
	<compiler meshdir="rollin-justin/meshes" texturedir="rollin-justin/textures" angle="radian" autolimits="true" balanceinertia="true" />
	<default>
		<default class="rollin-justin_visual">
			<geom contype="0" conaffinity="0"/>
		</default>
		<default class="rollin-justin_collision">
			<geom rgba="0.9 0.9 0.9 1.0"/>
		</default>
	</default>
	<asset>
		<mesh name="base" file="stl/base.stl" scale="1.0 1.0 1.0"/>
		<mesh name="torso1" file="stl/torso1.stl" scale="1.0 1.0 1.0"/>
		<mesh name="torso2" file="stl/torso2.stl" scale="1.0 1.0 1.0"/>
		<mesh name="torso3" file="stl/torso3.stl" scale="1.0 1.0 1.0"/>
		<mesh name="torso4" file="stl/torso4.stl" scale="1.0 1.0 1.0"/>
		<mesh name="head1" file="stl/head1.stl" scale="1.0 1.0 1.0"/>
		<mesh name="head2" file="stl/head2.stl" scale="1.0 1.0 1.0"/>
		<mesh name="left_arm1" file="stl/left_arm1.stl" scale="1.0 1.0 1.0"/>
		<mesh name="left_arm2" file="stl/left_arm2.stl" scale="1.0 1.0 1.0"/>
		<mesh name="left_arm3" file="stl/left_arm3.stl" scale="1.0 1.0 1.0"/>
		<mesh name="left_arm4" file="stl/left_arm4.stl" scale="1.0 1.0 1.0"/>
		<mesh name="left_arm5" file="stl/left_arm5.stl" scale="1.0 1.0 1.0"/>
		<mesh name="left_arm6" file="stl/left_arm6.stl" scale="1.0 1.0 1.0"/>
		<mesh name="finger_base" file="stl/finger-base.stl" scale="1.0 1.0 1.0"/>
		<mesh name="left_arm7" file="stl/left_arm7.stl" scale="1.0 1.0 1.0"/>
		<mesh name="finger_phaprox" file="stl/finger-phaprox.stl" scale="1.0 1.0 1.0"/>
		<mesh name="finger_phamed" file="stl/finger-phamed.stl" scale="1.0 1.0 1.0"/>
		<mesh name="hii2_geh_phadist_gesamt_asm" file="stl/hii2_geh_phadist_gesamt_asm.stl" scale="1.0 1.0 1.0"/>
		<mesh name="right_arm1" file="stl/right_arm1.stl" scale="1.0 1.0 1.0"/>
		<mesh name="right_arm2" file="stl/right_arm2.stl" scale="1.0 1.0 1.0"/>
		<mesh name="right_arm3" file="stl/right_arm3.stl" scale="1.0 1.0 1.0"/>
		<mesh name="right_arm4" file="stl/right_arm4.stl" scale="1.0 1.0 1.0"/>
		<mesh name="right_arm5" file="stl/right_arm5.stl" scale="1.0 1.0 1.0"/>
		<mesh name="right_arm6" file="stl/right_arm6.stl" scale="1.0 1.0 1.0"/>
		<mesh name="right_arm7" file="stl/right_arm7.stl" scale="1.0 1.0 1.0"/>
		<material name="M_base_link_collision_0" rgba="0.07340032607316971 0.11752369999885559 0.26214399933815 1.0"/>
		<material name="M_torso1_collision_0" rgba="0.11468800157308578 0.18363070487976074 0.40959998965263367 1.0"/>
		<material name="M_torso2_collision_0" rgba="0.7040000557899475 0.6880000233650208 0.6240000128746033 1.0"/>
		<material name="M_torso3_collision_0" rgba="0.7040000557899475 0.6880000233650208 0.6240000128746033 1.0"/>
		<material name="M_torso4_collision_0" rgba="0.1433599889278412 0.22953839600086212 0.5120000243186951 1.0"/>
		<material name="M_head1_collision_0" rgba="0.6399999856948853 0.6399999856948853 0.6399999856948853 1.0"/>
		<material name="M_head2_collision_0" rgba="0.2563522160053253 0.2769562005996704 0.29183998703956604 1.0"/>
		<material name="M_left_arm1_collision_0" rgba="0.5600000023841858 0.5499199628829956 0.459199994802475 1.0"/>
		<material name="M_left_arm2_collision_0" rgba="0.7027199864387512 0.7591999769210815 0.800000011920929 1.0"/>
		<material name="M_left_arm3_collision_0" rgba="0.5600000023841858 0.5499199628829956 0.459199994802475 1.0"/>
		<material name="M_left_arm4_collision_0" rgba="0.7027199864387512 0.7591999769210815 0.800000011920929 1.0"/>
		<material name="M_left_arm5_collision_0" rgba="0.800000011920929 0.7847999930381775 0.6480000019073486 1.0"/>
		<material name="M_left_arm6_collision_0" rgba="0.29600000381469727 0.4480000138282776 0.7360000610351562 1.0"/>
		<material name="M_left_arm7_collision_0" rgba="0.13750000298023224 0.19694800674915314 0.25 1.0"/>
		<material name="M_right_arm1_collision_0" rgba="0.5600000023841858 0.5499199628829956 0.459199994802475 1.0"/>
		<material name="M_right_arm2_collision_0" rgba="0.7027199864387512 0.7591999769210815 0.800000011920929 1.0"/>
		<material name="M_right_arm3_collision_0" rgba="0.5600000023841858 0.5499199628829956 0.459199994802475 1.0"/>
		<material name="M_right_arm4_collision_0" rgba="0.7027199864387512 0.7591999769210815 0.800000011920929 1.0"/>
		<material name="M_right_arm5_collision_0" rgba="0.6399999856948853 0.627839982509613 0.5184000134468079 1.0"/>
		<material name="M_right_arm6_collision_0" rgba="0.1515520066022873 0.22937600314617157 0.3768320083618164 1.0"/>
		<material name="M_right_arm7_collision_0" rgba="0.4672001004219055 0.4672001004219055 0.4672001004219055 1.0"/>
	</asset>
	<worldbody>
		<body name="rollin_justin" pos="0.0 0.0 0.0" quat="1.0 0.0 0.0 0.0">
			<joint name="odom_vel_lin_x_joint" type="slide" axis="1.0 0.0 0.0"/>
			<joint name="odom_vel_lin_y_joint" type="slide" axis="0.0 1.0 0.0"/>
			<joint name="odom_vel_ang_z_joint" type="hinge" axis="0.0 0.0 1.0"/>
			<body name="base_link" pos="0.0 0.0 0.0" quat="1.0 0.0 0.0 0.0">
				<inertial mass="224.73480224609375" pos="-0.0001827288797358051 1.61276911967434e-05 0.23259884119033813" quat="0.5002469420433044 0.500389039516449 0.49960505962371826 -0.4997585117816925" diaginertia="14.472882270812988 23.625009536743164 27.9912052154541"/>
				<geom name="SM_base_link_collision_0" type="mesh" pos="0.0 0.0 0.0" quat="1.0 0.0 0.0 0.0" mesh="base" material="M_base_link_collision_0" class="rollin-justin_collision"/>
				<body name="torso1" pos="0.0 0.0 0.6938999891281128" quat="1.0 0.0 0.0 0.0">
					<inertial mass="1.4712989330291748" pos="0.025275830179452896 0.0007431925623677671 -0.060477592051029205" quat="0.8976303935050964 0.01902051456272602 0.4402293562889099 -0.009795412421226501" diaginertia="0.007986107841134071 0.011889692395925522 0.01212779525667429"/>
					<geom name="SM_torso1_collision_0" type="mesh" pos="0.0 0.0 0.0" quat="1.0 0.0 0.0 0.0" mesh="torso1" material="M_torso1_collision_0" class="rollin-justin_collision"/>
					<joint name="torso1_joint" type="hinge" pos="0.0 0.0 0.0" range="-1.7453300952911377 3.3161301612854004" axis="0.0 0.0 1.0"/>
					<body name="torso2" pos="0.0 0.0 0.0" quat="0.5000031590461731 -0.5 -0.5 -0.4999968409538269">
						<inertial mass="6.738801002502441" pos="0.17496220767498016 -0.02361913211643696 3.1903075523587177e-06" quat="0.7064672112464905 -0.706275999546051 0.032233234494924545 -0.03223872184753418" diaginertia="0.037994228303432465 0.2922051250934601 0.3116662800312042"/>
						<geom name="SM_torso2_collision_0" type="mesh" pos="0.0 0.0 0.0" quat="1.0 0.0 0.0 0.0" mesh="torso2" material="M_torso2_collision_0" class="rollin-justin_collision"/>
						<joint name="torso2_joint" type="hinge" pos="0.0 0.0 0.0" range="-1.2217299938201904 0.5235999822616577" axis="0.0 0.0 1.0"/>
						<body name="torso3" pos="0.30000001192092896 -8.470329472543003e-22 0.0" quat="1.0 2.0536479054491018e-23 -1.6155871338926322e-27 0.0">
							<inertial mass="6.738801002502441" pos="0.17496220767498016 -0.02361913211643696 3.1903075523587177e-06" quat="0.7064672112464905 -0.706275999546051 0.032233234494924545 -0.03223872184753418" diaginertia="0.037994228303432465 0.2922051250934601 0.3116662800312042"/>
							<geom name="SM_torso3_collision_0" type="mesh" pos="0.0 0.0 0.0" quat="1.0 0.0 0.0 0.0" mesh="torso3" material="M_torso3_collision_0" class="rollin-justin_collision"/>
							<joint name="torso3_joint" type="hinge" pos="-1.0536230218007488e-21 -1.6653345369377348e-16 1.9006558680808532e-21" range="0.17453299462795258 2.338740110397339" axis="0.0 0.0 1.0"/>
							<body name="torso4" pos="0.30000001192092896 -1.6940658945086007e-21 6.462348535570529e-27" quat="1.0 2.0536479054491018e-23 -1.6155871338926322e-27 0.0">
								<inertial mass="7.379934787750244" pos="0.049072589725255966 0.07681142538785934 -3.748066592379473e-05" quat="0.6380517482757568 0.6382197737693787 0.30488279461860657 0.30432218313217163" diaginertia="0.07201972603797913 0.11302706599235535 0.13237376511096954"/>
								<geom name="SM_torso4_collision_0" type="mesh" pos="0.0 0.0 0.0" quat="1.0 0.0 0.0 0.0" mesh="torso4" material="M_torso4_collision_0" class="rollin-justin_collision"/>
								<joint name="torso4_joint" type="hinge" pos="-3.5121412786760217e-22 -5.551115123125783e-17 2.0452735347841183e-21" range="-1.5700000524520874 0.0" axis="0.0 0.0 1.0"/>
								<body name="left_arm1" pos="0.1899999976158142 0.08799999952316284 0.25600001215934753" quat="-1.2815869467885932e-06 0.9659269452095032 -3.433941628827597e-07 -0.25881481170654297">
									<inertial mass="2.2785184383392334" pos="-2.548355041653849e-06 -0.03233825042843819 0.07449404895305634" quat="0.7060986161231995 0.03782307729125023 -0.7060900926589966 -0.037828173488378525" diaginertia="0.006829762365669012 0.026606347411870956 0.02975747175514698"/>
									<geom name="SM_left_arm1_collision_0" type="mesh" pos="0.0 0.0 0.0" quat="1.0 0.0 0.0 0.0" mesh="left_arm1" material="M_left_arm1_collision_0" class="rollin-justin_collision"/>
									<joint name="left_arm1_joint" type="hinge" pos="3.512076655190666e-22 5.551106189575167e-17 -1.387813853239418e-17" range="-2.967060089111328 2.967060089111328" axis="0.0 0.0 1.0"/>
									<body name="left_arm2" pos="0.0 0.0 0.0" quat="0.7071090340614319 0.7071045637130737 3.921008487941007e-17 3.9296260555625847e-17">
										<inertial mass="2.279491424560547" pos="3.521484359225724e-06 -0.07504483312368393 -0.03232176601886749" quat="0.472882479429245 0.5257429480552673 -0.47289374470710754 -0.5256881713867188" diaginertia="0.006845936179161072 0.026855600997805595 0.03002067469060421"/>
										<geom name="SM_left_arm2_collision_0" type="mesh" pos="0.0 0.0 0.0" quat="1.0 0.0 0.0 0.0" mesh="left_arm2" material="M_left_arm2_collision_0" class="rollin-justin_collision"/>
										<joint name="left_arm2_joint" type="hinge" pos="0.0 0.0 -0.0" range="-2.094399929046631 2.094399929046631" axis="0.0 0.0 1.0"/>
										<body name="left_arm3" pos="-2.220446049250313e-16 -0.4000000059604645 0.0" quat="-0.49999797344207764 0.5000028610229492 0.5000001788139343 0.4999989867210388">
											<inertial mass="2.2785184383392334" pos="-2.548355041653849e-06 -0.03233825042843819 0.07449404895305634" quat="0.7060986161231995 0.03782307729125023 -0.7060900926589966 -0.037828173488378525" diaginertia="0.006829762365669012 0.026606347411870956 0.02975747175514698"/>
											<geom name="SM_left_arm3_collision_0" type="mesh" pos="0.0 0.0 0.0" quat="1.0 0.0 0.0 0.0" mesh="left_arm3" material="M_left_arm3_collision_0" class="rollin-justin_collision"/>
											<joint name="left_arm3_joint" type="hinge" pos="5.55122232573317e-17 9.614831788194643e-17 2.2204426081789649e-16" range="-2.967060089111328 2.967060089111328" axis="0.0 0.0 1.0"/>
											<body name="left_arm4" pos="-1.3877787807814457e-17 0.0 0.0" quat="0.7071090340614319 0.7071045637130737 -5.4967650555418635e-17 -6.3249128903851494e-18">
												<inertial mass="2.279491424560547" pos="3.521484359225724e-06 -0.07504483312368393 -0.03232176601886749" quat="0.472882479429245 0.5257429480552673 -0.47289374470710754 -0.5256881713867188" diaginertia="0.006845936179161072 0.026855600997805595 0.03002067469060421"/>
												<geom name="SM_left_arm4_collision_0" type="mesh" pos="0.0 0.0 0.0" quat="1.0 0.0 0.0 0.0" mesh="left_arm4" material="M_left_arm4_collision_0" class="rollin-justin_collision"/>
												<joint name="left_arm4_joint" type="hinge" pos="1.3877787807814457e-17 9.721435226537409e-23 -1.0364679981719312e-22" range="-2.094399929046631 2.094399929046631" axis="0.0 0.0 1.0"/>
												<body name="left_arm5" pos="1.3877787807814457e-17 -0.38999998569488525 -2.220446049250313e-16" quat="0.7071090340614319 -0.7071045637130737 1.4973237575545396e-22 5.98937076086506e-22">
													<inertial mass="1.2786158323287964" pos="-9.421699360245839e-06 0.024524187669157982 0.10406088083982468" quat="0.02889772318303585 0.7065482139587402 -0.02890058048069477 -0.706483781337738" diaginertia="0.0032310106325894594 0.019691383466124535 0.02106323093175888"/>
													<geom name="SM_left_arm5_collision_0" type="mesh" pos="0.0 0.0 0.0" quat="1.0 0.0 0.0 0.0" mesh="left_arm5" material="M_left_arm5_collision_0" class="rollin-justin_collision"/>
													<joint name="left_arm5_joint" type="hinge" pos="-1.3879634074941675e-17 -1.4869411926143026e-17 -2.478076149415833e-16" range="-2.967060089111328 2.967060089111328" axis="0.0 0.0 1.0"/>
													<body name="left_arm6" pos="0.0 0.0 0.0" quat="0.5000038146972656 -0.4999982714653015 0.49999934434890747 0.4999985694885254">
														<inertial mass="1.3991461992263794" pos="8.88389149622526e-06 0.0018555248389020562 -0.007509245071560144" quat="0.7144654393196106 0.6996655464172363 0.0003499173326417804 -0.002679457888007164" diaginertia="0.0027283544186502695 0.002825310919433832 0.002875787438824773"/>
														<geom name="SM_left_arm6_collision_0" type="mesh" pos="0.0 0.0 0.0" quat="1.0 0.0 0.0 0.0" mesh="left_arm6" material="M_left_arm6_collision_0" class="rollin-justin_collision"/>
														<joint name="left_arm6_joint" type="hinge" pos="-0.0 0.0 0.0" range="-0.785398006439209 1.3962599039077759" axis="0.0 0.0 1.0"/>
														<body name="left_arm7" pos="2.220446049250313e-16 -1.3877787807814457e-17 0.0" quat="0.5000036954879761 -0.49999913573265076 -0.499999463558197 -0.49999767541885376">
															<inertial mass="1.1577814817428589" pos="-0.027937384322285652 0.15548747777938843 0.0011196272680535913" quat="-0.5698389410972595 -0.3733614981174469 0.3872595727443695 0.6212204098701477" diaginertia="0.002662894083186984 0.03437979891896248 0.03506654500961304"/>
															<geom name="SM_left_arm7_collision_0" type="mesh" pos="0.0 0.0 0.0" quat="1.0 0.0 0.0 0.0" mesh="left_arm7" material="M_left_arm7_collision_0" class="rollin-justin_collision"/>
															<joint name="left_arm7_joint" type="hinge" pos="1.2015992018956641e-17 2.220446578645905e-16 -6.94176173909095e-18" range="-0.785398006439209 2.3561899662017822" axis="0.0 0.0 1.0"/>
															<body name="left_1thumb_base" pos="-0.05040000006556511 0.2029000073671341 -0.04619999974966049" quat="0.3802274763584137 0.28664183616638184 0.5528058409690857 0.6838634610176086">
																<body name="left_1thumb1" pos="0.0 0.0 0.0" quat="1.0 6.071532165918825e-18 3.0814879110195774e-33 8.673617379884035e-19">
																	<inertial mass="0.001" pos="0.0 0.0 0.0" quat="1.0 0.0 0.0 0.0" diaginertia="0.0001 0.0001 0.0001"/>
																	<joint name="left_1thumb1_joint" type="hinge" pos="0.0 0.0 0.0" range="-0.5235990285873413 0.5235990285873413" axis="0.0 0.0 1.0"/>
																	<body name="left_1thumb2" pos="0.0 0.0 0.0" quat="0.7071090340614319 0.7071045637130737 2.3919178109056975e-17 -8.58644660539136e-18">
																		<inertial mass="0.06310640275478363" pos="0.04163796454668045 -0.0016735829412937164 -0.0008487995364703238" quat="0.7089323997497559 -0.7050620913505554 0.016155026853084564 -0.006425212137401104" diaginertia="1.090284604288172e-05 0.0001451448624720797 0.00014662386092823"/>
																		<geom name="SM_left_1thumb2_collision_0" type="mesh" pos="0.0 0.0 0.0" quat="1.0 0.0 0.0 0.0" mesh="finger_phaprox" class="rollin-justin_collision"/>
																		<joint name="left_1thumb2_joint" type="hinge" pos="0.0 0.0 0.0" range="-0.34906598925590515 1.500980019569397" axis="0.0 0.0 1.0"/>
																		<body name="left_1thumb3" pos="0.07500000298023224 0.0 -1.1102230246251565e-16" quat="1.0 0.0 0.0 0.0">
																			<inertial mass="0.02652239054441452" pos="0.019823182374238968 -0.0014702541520819068 0.0006521216128021479" quat="0.7099600434303284 -0.7039279937744141 0.006069484166800976 -0.020131085067987442" diaginertia="4.763823199027684e-06 1.7667940483079292e-05 1.8650636775419116e-05"/>
																			<geom name="SM_left_1thumb3_collision_0" type="mesh" pos="0.0 0.0 0.0" quat="1.0 0.0 0.0 0.0" mesh="finger_phamed" class="rollin-justin_collision"/>
																			<joint name="left_1thumb3_joint" type="hinge" pos="-1.119974838846279e-17 1.4848274483642091e-16 -1.5067052506006036e-16" range="-0.17453299462795258 1.7627800703048706" axis="0.0 0.0 1.0"/>
																			<body name="left_1thumb4" pos="0.03999000042676926 -2.220446049250313e-16 -1.1102230246251565e-16" quat="0.7071090340614319 0.0 0.0 -0.7071045637130737">
																				<inertial mass="0.02797284722328186" pos="-0.002071711700409651 0.02310049533843994 0.000411754910601303" quat="0.44483330845832825 0.4916505813598633 0.5386422872543335 0.5198726058006287" diaginertia="2.3384186533803586e-06 1.9123144738841802e-05 1.9700763004948385e-05"/>
																				<geom name="SM_left_1thumb4_collision_0" type="mesh" pos="0.0 0.0 0.0" quat="1.0 0.0 0.0 0.0" mesh="hii2_geh_phadist_gesamt_asm" class="rollin-justin_collision"/>
																				<joint name="left_1thumb4_joint" type="hinge" pos="2.1631920483207407e-16 1.1503569015039434e-16 4.871265634708045e-17" range="-0.17453299462795258 1.7627800703048706" axis="0.0 0.0 1.0"/>
																			</body>
																		</body>
																	</body>
																</body>
															</body>
															<body name="left_2tip_base" pos="0.04820000007748604 0.24089999496936798 -0.023600000888109207" quat="-0.5390362739562988 0.5562926530838013 0.5027128458023071 -0.3837422728538513">
																<body name="left_2tip1" pos="4.440892098500626e-16 5.551115123125783e-17 1.1102230246251565e-16" quat="1.0 3.469446951953614e-18 -1.3877787807814457e-17 -3.469446951953614e-18">
																	<inertial mass="0.001" pos="0.0 0.0 0.0" quat="1.0 0.0 0.0 0.0" diaginertia="0.0001 0.0001 0.0001"/>
																	<joint name="left_2tip1_joint" type="hinge" pos="-6.3397650010016e-17 -4.565960218931868e-16 -1.1111124257633858e-17" range="-0.5235990285873413 0.5235990285873413" axis="0.0 0.0 1.0"/>
																	<body name="left_2tip2" pos="4.440892098500626e-16 5.551115123125783e-17 1.1102230246251565e-16" quat="0.7071090340614319 0.7071045637130737 9.813047093147255e-18 4.415864988061671e-17">
																		<inertial mass="0.06310640275478363" pos="0.04163796454668045 -0.0016735829412937164 -0.0008487995364703238" quat="0.7089323997497559 -0.7050620913505554 0.016155026853084564 -0.006425212137401104" diaginertia="1.090284604288172e-05 0.0001451448624720797 0.00014662386092823"/>
																		<geom name="SM_left_2tip2_collision_0" type="mesh" pos="0.0 0.0 0.0" quat="1.0 0.0 0.0 0.0" mesh="finger_phaprox" class="rollin-justin_collision"/>
																		<joint name="left_2tip2_joint" type="hinge" pos="-6.3397650010016e-17 -4.565960218931868e-16 -1.1111124257633858e-17" range="-0.34906598925590515 1.500980019569397" axis="0.0 0.0 1.0"/>
																		<body name="left_2tip3" pos="0.07500000298023224 -1.1102230246251565e-16 -1.6653345369377348e-16" quat="1.0 -6.938893903907228e-18 -6.938893903907228e-18 5.551115123125783e-17">
																			<inertial mass="0.02652239054441452" pos="0.019823182374238968 -0.0014702541520819068 0.0006521216128021479" quat="0.7099600434303284 -0.7039279937744141 0.006069484166800976 -0.020131085067987442" diaginertia="4.763823199027684e-06 1.7667940483079292e-05 1.8650636775419116e-05"/>
																			<geom name="SM_left_2tip3_collision_0" type="mesh" pos="0.0 0.0 0.0" quat="1.0 0.0 0.0 0.0" mesh="finger_phamed" class="rollin-justin_collision"/>
																			<joint name="left_2tip3_joint" type="hinge" pos="2.641402895189979e-16 -1.252385990467664e-16 5.870309960177909e-16" range="-0.17453299462795258 1.7627800703048706" axis="0.0 0.0 1.0"/>
																			<body name="left_2tip4" pos="0.03999999910593033 1.1102230246251565e-16 -1.1102230246251565e-16" quat="0.7071090340614319 1.2416987454718263e-22 -5.3971632453676184e-17 -0.7071045637130737">
																				<inertial mass="0.02797284722328186" pos="-0.002071711700409651 0.02310049533843994 0.000411754910601303" quat="0.44483330845832825 0.4916505813598633 0.5386422872543335 0.5198726058006287" diaginertia="2.3384186533803586e-06 1.9123144738841802e-05 1.9700763004948385e-05"/>
																				<geom name="SM_left_2tip4_collision_0" type="mesh" pos="0.0 0.0 0.0" quat="1.0 0.0 0.0 0.0" mesh="hii2_geh_phadist_gesamt_asm" class="rollin-justin_collision"/>
																				<joint name="left_2tip4_joint" type="hinge" pos="-5.628677533059165e-17 -1.047256514385293e-16 -4.220430068758421e-16" range="-0.17453299462795258 1.7627800703048706" axis="0.0 0.0 1.0"/>
																			</body>
																		</body>
																	</body>
																</body>
															</body>
															<body name="left_3middle_base" pos="0.04690000042319298 0.2353000044822693 0.016289999708533287" quat="-0.5390362739562988 0.5562926530838013 0.5027128458023071 -0.3837422728538513">
																<inertial mass="0.10227024555206299" pos="-0.04256020858883858 0.00015783606795594096 0.0005033219931647182" quat="-0.6848095059394836 0.7286955714225769 -0.004266374744474888 -0.004536719061434269" diaginertia="2.8367161576170474e-05 0.0002721700584515929 0.0002832259051501751"/>
																<geom name="SM_left_3middle_base_collision_0" type="mesh" pos="0.0 0.0 0.0" quat="1.0 0.0 0.0 0.0" mesh="finger_base" class="rollin-justin_collision"/>
																<body name="left_3middle1" pos="4.440892098500626e-16 5.551115123125783e-17 0.0" quat="1.0 3.469446951953614e-18 -1.3877787807814457e-17 -3.469446951953614e-18">
																	<inertial mass="0.001" pos="0.0 0.0 0.0" quat="1.0 0.0 0.0 0.0" diaginertia="0.0001 0.0001 0.0001"/>
																	<joint name="left_3middle1_joint" type="hinge" pos="9.848323864730804e-18 -4.3779276396686817e-16 -9.239713321335726e-17" range="-0.5235990285873413 0.5235990285873413" axis="0.0 0.0 1.0"/>
																	<body name="left_3middle2" pos="4.440892098500626e-16 5.551115123125783e-17 0.0" quat="0.7071090340614319 0.7071045637130737 9.813047093147255e-18 4.415864988061671e-17">
																		<inertial mass="0.06310640275478363" pos="0.04163796454668045 -0.0016735829412937164 -0.0008487995364703238" quat="0.7089323997497559 -0.7050620913505554 0.016155026853084564 -0.006425212137401104" diaginertia="1.090284604288172e-05 0.0001451448624720797 0.00014662386092823"/>
																		<geom name="SM_left_3middle2_collision_0" type="mesh" pos="0.0 0.0 0.0" quat="1.0 0.0 0.0 0.0" mesh="finger_phaprox" class="rollin-justin_collision"/>
																		<joint name="left_3middle2_joint" type="hinge" pos="9.848323864730804e-18 -4.3779276396686817e-16 -9.239713321335726e-17" range="-0.34906598925590515 1.500980019569397" axis="0.0 0.0 1.0"/>
																		<body name="left_3middle3" pos="0.07498999685049057 -2.220446049250313e-16 0.0" quat="1.0 -6.938893903907228e-18 -6.938893903907228e-18 5.551115123125783e-17">
																			<inertial mass="0.02652239054441452" pos="0.019823182374238968 -0.0014702541520819068 0.0006521216128021479" quat="0.7099600434303284 -0.7039279937744141 0.006069484166800976 -0.020131085067987442" diaginertia="4.763823199027684e-06 1.7667940483079292e-05 1.8650636775419116e-05"/>
																			<geom name="SM_left_3middle3_collision_0" type="mesh" pos="0.0 0.0 0.0" quat="1.0 0.0 0.0 0.0" mesh="finger_phamed" class="rollin-justin_collision"/>
																			<joint name="left_3middle3_joint" type="hinge" pos="2.287408238895502e-16 7.966926542333442e-17 5.466105308352565e-16" range="-0.17453299462795258 1.7627800703048706" axis="0.0 0.0 1.0"/>
																			<body name="left_3middle4" pos="0.03999999910593033 -1.1102230246251565e-16 -5.551115123125783e-17" quat="0.7071090340614319 1.2416987454718263e-22 -5.3971632453676184e-17 -0.7071045637130737">
																				<inertial mass="0.02797284722328186" pos="-0.002071711700409651 0.02310049533843994 0.000411754910601303" quat="0.44483330845832825 0.4916505813598633 0.5386422872543335 0.5198726058006287" diaginertia="2.3384186533803586e-06 1.9123144738841802e-05 1.9700763004948385e-05"/>
																				<geom name="SM_left_3middle4_collision_0" type="mesh" pos="0.0 0.0 0.0" quat="1.0 0.0 0.0 0.0" mesh="hii2_geh_phadist_gesamt_asm" class="rollin-justin_collision"/>
																				<joint name="left_3middle4_joint" type="hinge" pos="7.1989594884939e-17 8.461759219652464e-17 -4.1312086473527774e-16" range="-0.17453299462795258 1.7627800703048706" axis="0.0 0.0 1.0"/>
																			</body>
																		</body>
																	</body>
																</body>
															</body>
															<body name="left_4ring_base" pos="0.03739999979734421 0.22990000247955322 0.062300000339746475" quat="-0.5390362739562988 0.5562926530838013 0.5027128458023071 -0.3837422728538513">
																<body name="left_4ring1" pos="4.440892098500626e-16 5.551115123125783e-17 -1.1102230246251565e-16" quat="1.0 3.469446951953614e-18 -1.3877787807814457e-17 -3.469446951953614e-18">
																	<inertial mass="0.001" pos="0.0 0.0 0.0" quat="1.0 0.0 0.0 0.0" diaginertia="0.0001 0.0001 0.0001"/>
																	<joint name="left_4ring1_joint" type="hinge" pos="8.309429608511639e-17 -4.1898945310099036e-16 -1.7368313968753882e-16" range="-0.5235990285873413 0.5235990285873413" axis="0.0 0.0 1.0"/>
																	<body name="left_4ring2" pos="4.440892098500626e-16 5.551115123125783e-17 -1.1102230246251565e-16" quat="0.7071090340614319 0.7071045637130737 9.813047093147255e-18 4.415864988061671e-17">
																		<inertial mass="0.06310640275478363" pos="0.04163796454668045 -0.0016735829412937164 -0.0008487995364703238" quat="0.7089323997497559 -0.7050620913505554 0.016155026853084564 -0.006425212137401104" diaginertia="1.090284604288172e-05 0.0001451448624720797 0.00014662386092823"/>
																		<geom name="SM_left_4ring2_collision_0" type="mesh" pos="0.0 0.0 0.0" quat="1.0 0.0 0.0 0.0" mesh="finger_phaprox" class="rollin-justin_collision"/>
																		<joint name="left_4ring2_joint" type="hinge" pos="8.309429608511639e-17 -4.1898945310099036e-16 -1.7368313968753882e-16" range="-0.34906598925590515 1.500980019569397" axis="0.0 0.0 1.0"/>
																		<body name="left_4ring3" pos="0.07500000298023224 -2.220446049250313e-16 -5.551115123125783e-17" quat="1.0 -6.938893903907228e-18 -6.938893903907228e-18 5.551115123125783e-17">
																			<inertial mass="0.02652239054441452" pos="0.019823182374238968 -0.0014702541520819068 0.0006521216128021479" quat="0.7099600434303284 -0.7039279937744141 0.006069484166800976 -0.020131085067987442" diaginertia="4.763823199027684e-06 1.7667940483079292e-05 1.8650636775419116e-05"/>
																			<geom name="SM_left_4ring3_collision_0" type="mesh" pos="0.0 0.0 0.0" quat="1.0 0.0 0.0 0.0" mesh="finger_phamed" class="rollin-justin_collision"/>
																			<joint name="left_4ring3_joint" type="hinge" pos="2.222708156615074e-16 8.562226591619685e-17 1.6792266713660934e-16" range="-0.17453299462795258 1.7627800703048706" axis="0.0 0.0 1.0"/>
																			<body name="left_4ring4" pos="0.03999999910593033 -1.1102230246251565e-16 -5.551115123125783e-17" quat="0.7071090340614319 1.2416987454718263e-22 -5.3971632453676184e-17 -0.7071045637130737">
																				<inertial mass="0.02797284722328186" pos="-0.002071711700409651 0.02310049533843994 0.000411754910601303" quat="0.44483330845832825 0.4916505813598633 0.5386422872543335 0.5198726058006287" diaginertia="2.3384186533803586e-06 1.9123144738841802e-05 1.9700763004948385e-05"/>
																				<geom name="SM_left_4ring4_collision_0" type="mesh" pos="0.0 0.0 0.0" quat="1.0 0.0 0.0 0.0" mesh="hii2_geh_phadist_gesamt_asm" class="rollin-justin_collision"/>
																				<joint name="left_4ring4_joint" type="hinge" pos="1.2306275669372733e-16 2.939276457121837e-17 2.4551354200923077e-17" range="-0.17453299462795258 1.7627800703048706" axis="0.0 0.0 1.0"/>
																			</body>
																		</body>
																	</body>
																</body>
															</body>
															<body name="left_palm" pos="0.0 0.10109999775886536 0.0" quat="9.381886343362567e-07 9.381827226206951e-07 0.7071045637130737 0.7071090340614319">
															</body>
														</body>
													</body>
												</body>
											</body>
										</body>
									</body>
								</body>
								<body name="right_arm1" pos="0.1899999976158142 0.08799999952316284 -0.25600001215934753" quat="0.25881481170654297 9.381927839058335e-07 0.9659269452095032 9.381927839058335e-07">
									<inertial mass="2.278517484664917" pos="-2.5484271191089647e-06 0.032338276505470276 -0.07449407130479813" quat="-0.7060900926589966 -0.037828292697668076 0.7060986161231995 0.037823162972927094" diaginertia="0.006829758640378714 0.02660633623600006 0.029757458716630936"/>
									<geom name="SM_right_arm1_collision_0" type="mesh" pos="0.0 0.0 0.0" quat="1.0 0.0 0.0 0.0" mesh="right_arm1" material="M_right_arm1_collision_0" class="rollin-justin_collision"/>
									<joint name="right_arm1_joint" type="hinge" pos="1.75603840332598e-21 2.7755583556562794e-16 1.3876031703374007e-17" range="-2.967060089111328 2.967060089111328" axis="0.0 0.0 1.0"/>
									<body name="right_arm2" pos="-2.220446049250313e-16 0.0 -1.1102230246251565e-16" quat="0.7071090340614319 0.7071045637130737 -2.994620756947174e-22 5.989454064576651e-22">
										<inertial mass="2.2794909477233887" pos="3.5223188206146006e-06 0.07504486292600632 0.032321762293577194" quat="-0.4728938043117523 -0.5256880521774292 0.47288253903388977 0.5257428884506226" diaginertia="0.006845939438790083 0.02685561217367649 0.030020706355571747"/>
										<geom name="SM_right_arm2_collision_0" type="mesh" pos="0.0 0.0 0.0" quat="1.0 0.0 0.0 0.0" mesh="right_arm2" material="M_right_arm2_collision_0" class="rollin-justin_collision"/>
										<joint name="right_arm2_joint" type="hinge" pos="-9.614862228441185e-17 2.2204404905965967e-16 5.551252104235221e-17" range="-2.094399929046631 2.094399929046631" axis="0.0 0.0 1.0"/>
										<body name="right_arm3" pos="2.220446049250313e-16 0.4000000059604645 -1.3877787807814457e-17" quat="-0.5 0.49999889731407166 0.49999815225601196 0.5000029802322388">
											<inertial mass="2.278517484664917" pos="-2.5484271191089647e-06 0.032338276505470276 -0.07449407130479813" quat="-0.7060900926589966 -0.037828292697668076 0.7060986161231995 0.037823162972927094" diaginertia="0.006829758640378714 0.02660633623600006 0.029757458716630936"/>
											<geom name="SM_right_arm3_collision_0" type="mesh" pos="0.0 0.0 0.0" quat="1.0 0.0 0.0 0.0" mesh="right_arm3" material="M_right_arm3_collision_0" class="rollin-justin_collision"/>
											<joint name="right_arm3_joint" type="hinge" pos="-1.2018573649648419e-17 6.935169936789515e-18 2.220447108041497e-16" range="-2.967060089111328 2.967060089111328" axis="0.0 0.0 1.0"/>
											<body name="right_arm4" pos="0.0 0.0 0.0" quat="0.7071090340614319 0.7071045637130737 1.497364021015142e-22 -1.4973573314746658e-22">
												<inertial mass="2.2794909477233887" pos="3.5223188206146006e-06 0.07504486292600632 0.032321762293577194" quat="-0.4728938043117523 -0.5256880521774292 0.47288253903388977 0.5257428884506226" diaginertia="0.006845939438790083 0.02685561217367649 0.030020706355571747"/>
												<geom name="SM_right_arm4_collision_0" type="mesh" pos="0.0 0.0 0.0" quat="1.0 0.0 0.0 0.0" mesh="right_arm4" material="M_right_arm4_collision_0" class="rollin-justin_collision"/>
												<joint name="right_arm4_joint" type="hinge" pos="-0.0 0.0 0.0" range="-2.094399929046631 2.094399929046631" axis="0.0 0.0 1.0"/>
												<body name="right_arm5" pos="0.0 0.38999998569488525 2.220446049250313e-16" quat="-9.381886343362567e-07 -9.381827226206951e-07 0.7071045637130737 0.7071090340614319">
													<inertial mass="1.2786149978637695" pos="9.436078471480869e-06 0.024524202570319176 -0.10406084358692169" quat="-0.7064837217330933 -0.028900451958179474 0.7065482139587402 0.02889792062342167" diaginertia="0.0032310059759765863 0.019691376015543938 0.021063216030597687"/>
													<geom name="SM_right_arm5_collision_0" type="mesh" pos="0.0 0.0 0.0" quat="1.0 0.0 0.0 0.0" mesh="right_arm5" material="M_right_arm5_collision_0" class="rollin-justin_collision"/>
													<joint name="right_arm5_joint" type="hinge" pos="-2.4494946473744053e-21 -2.0716787410482841e-16 -1.3678900501332207e-16" range="-2.967060089111328 2.967060089111328" axis="0.0 0.0 1.0"/>
													<body name="right_arm6" pos="0.0 -2.220446049250313e-16 0.0" quat="0.5000036358833313 0.4999975860118866 -0.4999995231628418 0.4999992549419403">
														<inertial mass="1.3991411924362183" pos="-8.879690540197771e-06 0.0018555446295067668 0.007509254850447178" quat="0.7144685387611389 -0.6996623873710632 0.00035004265373572707 0.0026774080470204353" diaginertia="0.002728336723521352 0.0028252939227968454 0.002875769278034568"/>
														<geom name="SM_right_arm6_collision_0" type="mesh" pos="0.0 0.0 0.0" quat="1.0 0.0 0.0 0.0" mesh="right_arm6" material="M_right_arm6_collision_0" class="rollin-justin_collision"/>
														<joint name="right_arm6_joint" type="hinge" pos="2.2572541167769954e-21 1.110199069474617e-16 -1.9229765485040753e-16" range="-0.785398006439209 1.3962599039077759" axis="0.0 0.0 1.0"/>
														<body name="right_arm7" pos="0.0 0.0 0.0" quat="0.5000005960464478 0.5000025629997253 0.4999975562095642 -0.4999992847442627">
															<inertial mass="0.9010521173477173" pos="0.012301264330744743 0.17445337772369385 0.004564546514302492" quat="-0.3556727468967438 -0.5755924582481384 0.6251567602157593 0.3890620172023773" diaginertia="0.002122175879776478 0.030409911647439003 0.031320974230766296"/>
															<geom name="SM_right_arm7_collision_0" type="mesh" pos="0.0 0.0 0.0" quat="1.0 0.0 0.0 0.0" mesh="right_arm7" material="M_right_arm7_collision_0" class="rollin-justin_collision"/>
															<joint name="right_arm7_joint" type="hinge" pos="0.0 0.0 -0.0" range="-0.785398006439209 2.3561899662017822" axis="0.0 0.0 1.0"/>
															<body name="right_1thumb_base" pos="-0.05040000006556511 0.2029000073671341 0.04619999974966049" quat="0.287274032831192 0.3797719180583954 0.6829645037651062 0.5539010763168335">
																<body name="right_1thumb1" pos="0.0 0.0 2.220446049250313e-16" quat="1.0 1.3877787807814457e-17 1.734723475976807e-18 -1.3010426069826053e-18">
																	<inertial mass="0.001" pos="0.0 0.0 0.0" quat="1.0 0.0 0.0 0.0" diaginertia="0.0001 0.0001 0.0001"/>
																	<joint name="right_1thumb1_joint" type="hinge" pos="1.2167786278805022e-17 -4.9424385707178226e-17 -2.1613186496694306e-16" range="-0.5235990285873413 0.5235990285873413" axis="0.0 0.0 1.0"/>
																	<body name="right_1thumb2" pos="0.0 0.0 2.220446049250313e-16" quat="0.7071090340614319 0.7071045637130737 3.97693631982531e-18 -3.3828159128106293e-18">
																		<inertial mass="0.06310640275478363" pos="0.04163796454668045 -0.0016735829412937164 -0.0008487995364703238" quat="0.7089323997497559 -0.7050620913505554 0.016155026853084564 -0.006425212137401104" diaginertia="1.090284604288172e-05 0.0001451448624720797 0.00014662386092823"/>
																		<geom name="SM_right_1thumb2_collision_0" type="mesh" pos="0.0 0.0 0.0" quat="1.0 0.0 0.0 0.0" mesh="finger_phaprox" class="rollin-justin_collision"/>
																		<joint name="right_1thumb2_joint" type="hinge" pos="1.2167786278805022e-17 -4.9424385707178226e-17 -2.1613186496694306e-16" range="-0.34906598925590515 1.500980019569397" axis="0.0 0.0 1.0"/>
																		<body name="right_1thumb3" pos="0.07500000298023224 4.440892098500626e-16 0.0" quat="1.0 1.3877787807814457e-17 8.673617379884035e-19 5.7777898331617076e-34">
																			<inertial mass="0.02652239054441452" pos="0.019823182374238968 -0.0014702541520819068 0.0006521216128021479" quat="0.7099600434303284 -0.7039279937744141 0.006069484166800976 -0.020131085067987442" diaginertia="4.763823199027684e-06 1.7667940483079292e-05 1.8650636775419116e-05"/>
																			<geom name="SM_right_1thumb3_collision_0" type="mesh" pos="0.0 0.0 0.0" quat="1.0 0.0 0.0 0.0" mesh="finger_phamed" class="rollin-justin_collision"/>
																			<joint name="right_1thumb3_joint" type="hinge" pos="4.444228349521624e-16 1.7308264626749473e-17 -3.3724550620480964e-17" range="-0.17453299462795258 1.7627800703048706" axis="0.0 0.0 1.0"/>
																			<body name="right_1thumb4" pos="0.03999999910593033 2.220446049250313e-16 0.0" quat="0.7071090340614319 3.679861433862097e-18 1.4719508601174942e-17 -0.7071045637130737">
																				<inertial mass="0.02797284722328186" pos="-0.002071711700409651 0.02310049533843994 0.000411754910601303" quat="0.44483330845832825 0.4916505813598633 0.5386422872543335 0.5198726058006287" diaginertia="2.3384186533803586e-06 1.9123144738841802e-05 1.9700763004948385e-05"/>
																				<geom name="SM_right_1thumb4_collision_0" type="mesh" pos="0.0 0.0 0.0" quat="1.0 0.0 0.0 0.0" mesh="hii2_geh_phadist_gesamt_asm" class="rollin-justin_collision"/>
																				<joint name="right_1thumb4_joint" type="hinge" pos="2.269289145362548e-16 -2.8201581475750155e-17 -1.7919770798596854e-16" range="-0.17453299462795258 1.7627800703048706" axis="0.0 0.0 1.0"/>
																			</body>
																		</body>
																	</body>
																</body>
															</body>
															<body name="right_3middle_base" pos="0.04690000042319298 0.2353000044822693 -0.016289999708533287" quat="0.5554459691047668 -0.5398693680763245 -0.38459038734436035 0.5021066069602966">
																<body name="right_3middle1" pos="0.0 0.0 -2.220446049250313e-16" quat="1.0 6.938893903907228e-18 2.7755575615628914e-17 7.703719777548943e-34">
																	<inertial mass="0.001" pos="0.0 0.0 0.0" quat="1.0 0.0 0.0 0.0" diaginertia="0.0001 0.0001 0.0001"/>
																	<joint name="right_3middle1_joint" type="hinge" pos="1.4647904869502146e-16 -3.707859595081608e-17 -1.6270486477218404e-16" range="-0.5235990285873413 0.5235990285873413" axis="0.0 0.0 1.0"/>
																	<body name="right_3middle2" pos="0.0 0.0 -2.220446049250313e-16" quat="0.7071090340614319 0.7071045637130737 -4.906461508027686e-18 -3.9251940218405255e-17">
																		<inertial mass="0.06310640275478363" pos="0.04163796454668045 -0.0016735829412937164 -0.0008487995364703238" quat="0.7089323997497559 -0.7050620913505554 0.016155026853084564 -0.006425212137401104" diaginertia="1.090284604288172e-05 0.0001451448624720797 0.00014662386092823"/>
																		<geom name="SM_right_3middle2_collision_0" type="mesh" pos="0.0 0.0 0.0" quat="1.0 0.0 0.0 0.0" mesh="finger_phaprox" class="rollin-justin_collision"/>
																		<joint name="right_3middle2_joint" type="hinge" pos="1.4647904869502146e-16 -3.707859595081608e-17 -1.6270486477218404e-16" range="-0.34906598925590515 1.500980019569397" axis="0.0 0.0 1.0"/>
																		<body name="right_3middle3" pos="0.07500000298023224 0.0 1.1102230246251565e-16" quat="1.0 6.071532165918825e-18 5.204170427930421e-18 1.3877787807814457e-17">
																			<inertial mass="0.02652239054441452" pos="0.019823182374238968 -0.0014702541520819068 0.0006521216128021479" quat="0.7099600434303284 -0.7039279937744141 0.006069484166800976 -0.020131085067987442" diaginertia="4.763823199027684e-06 1.7667940483079292e-05 1.8650636775419116e-05"/>
																			<geom name="SM_right_3middle3_collision_0" type="mesh" pos="0.0 0.0 0.0" quat="1.0 0.0 0.0 0.0" mesh="finger_phamed" class="rollin-justin_collision"/>
																			<joint name="right_3middle3_joint" type="hinge" pos="-5.251291929577362e-17 5.947727051021278e-17 -1.964154128792557e-16" range="-0.17453299462795258 1.7627800703048706" axis="0.0 0.0 1.0"/>
																			<body name="right_3middle4" pos="0.03999999910593033 0.0 5.551115123125783e-17" quat="0.7071090340614319 4.051696407279485e-17 3.549565349979785e-17 -0.7071045637130737">
																				<inertial mass="0.02797284722328186" pos="-0.002071711700409651 0.02310049533843994 0.000411754910601303" quat="0.44483330845832825 0.4916505813598633 0.5386422872543335 0.5198726058006287" diaginertia="2.3384186533803586e-06 1.9123144738841802e-05 1.9700763004948385e-05"/>
																				<geom name="SM_right_3middle4_collision_0" type="mesh" pos="0.0 0.0 0.0" quat="1.0 0.0 0.0 0.0" mesh="hii2_geh_phadist_gesamt_asm" class="rollin-justin_collision"/>
																				<joint name="right_3middle4_joint" type="hinge" pos="1.8385460579446653e-17 -1.7377350751509902e-17 -4.813266310959338e-16" range="-0.17453299462795258 1.7627800703048706" axis="0.0 0.0 1.0"/>
																			</body>
																		</body>
																	</body>
																</body>
															</body>
															<body name="right_4ring_base" pos="0.03739999979734421 0.22990000247955322 -0.062300000339746475" quat="0.5554459691047668 -0.5398693680763245 -0.38459038734436035 0.5021066069602966">
																<body name="right_4ring1" pos="-4.440892098500626e-16 5.551115123125783e-17 -4.440892098500626e-16" quat="1.0 6.938893903907228e-18 2.7755575615628914e-17 7.703719777548943e-34">
																	<inertial mass="0.001" pos="0.0 0.0 0.0" quat="1.0 0.0 0.0 0.0" diaginertia="0.0001 0.0001 0.0001"/>
																	<joint name="right_4ring1_joint" type="hinge" pos="2.831675082505265e-16 -5.122396808411307e-16 -2.343898983730259e-16" range="-0.5235990285873413 0.5235990285873413" axis="0.0 0.0 1.0"/>
																	<body name="right_4ring2" pos="-4.440892098500626e-16 5.551115123125783e-17 -4.440892098500626e-16" quat="0.7071090340614319 0.7071045637130737 -4.906461508027686e-18 -3.9251940218405255e-17">
																		<inertial mass="0.06310640275478363" pos="0.04163796454668045 -0.0016735829412937164 -0.0008487995364703238" quat="0.7089323997497559 -0.7050620913505554 0.016155026853084564 -0.006425212137401104" diaginertia="1.090284604288172e-05 0.0001451448624720797 0.00014662386092823"/>
																		<geom name="SM_right_4ring2_collision_0" type="mesh" pos="0.0 0.0 0.0" quat="1.0 0.0 0.0 0.0" mesh="finger_phaprox" class="rollin-justin_collision"/>
																		<joint name="right_4ring2_joint" type="hinge" pos="2.831675082505265e-16 -5.122396808411307e-16 -2.343898983730259e-16" range="-0.34906598925590515 1.500980019569397" axis="0.0 0.0 1.0"/>
																		<body name="right_4ring3" pos="0.07500000298023224 1.1102230246251565e-16 5.551115123125783e-17" quat="1.0 6.071532165918825e-18 5.204170427930421e-18 1.3877787807814457e-17">
																			<inertial mass="0.02652239054441452" pos="0.019823182374238968 -0.0014702541520819068 0.0006521216128021479" quat="0.7099600434303284 -0.7039279937744141 0.006069484166800976 -0.020131085067987442" diaginertia="4.763823199027684e-06 1.7667940483079292e-05 1.8650636775419116e-05"/>
																			<geom name="SM_right_4ring3_collision_0" type="mesh" pos="0.0 0.0 0.0" quat="1.0 0.0 0.0 0.0" mesh="finger_phamed" class="rollin-justin_collision"/>
																			<joint name="right_4ring3_joint" type="hinge" pos="6.656433562288541e-17 9.314140385875287e-17 -1.8668026469311502e-16" range="-0.17453299462795258 1.7627800703048706" axis="0.0 0.0 1.0"/>
																			<body name="right_4ring4" pos="0.03999999910593033 0.0 5.551115123125783e-17" quat="0.7071090340614319 4.051696407279485e-17 3.549565349979785e-17 -0.7071045637130737">
																				<inertial mass="0.02797284722328186" pos="-0.002071711700409651 0.02310049533843994 0.000411754910601303" quat="0.44483330845832825 0.4916505813598633 0.5386422872543335 0.5198726058006287" diaginertia="2.3384186533803586e-06 1.9123144738841802e-05 1.9700763004948385e-05"/>
																				<geom name="SM_right_4ring4_collision_0" type="mesh" pos="0.0 0.0 0.0" quat="1.0 0.0 0.0 0.0" mesh="hii2_geh_phadist_gesamt_asm" class="rollin-justin_collision"/>
																				<joint name="right_4ring4_joint" type="hinge" pos="-3.2633876586882844e-17 3.646948992623408e-17 -4.3476437633497273e-17" range="-0.17453299462795258 1.7627800703048706" axis="0.0 0.0 1.0"/>
																			</body>
																		</body>
																	</body>
																</body>
															</body>
															<body name="right_2tip_base" pos="0.04820000007748604 0.24089999496936798 0.023600000888109207" quat="0.5554459691047668 -0.5398693680763245 -0.38459038734436035 0.5021066069602966">
																<body name="right_2tip1" pos="0.0 5.551115123125783e-17 0.0" quat="1.0 6.938893903907228e-18 2.7755575615628914e-17 7.703719777548943e-34">
																	<inertial mass="0.001" pos="0.0 0.0 0.0" quat="1.0 0.0 0.0 0.0" diaginertia="0.0001 0.0001 0.0001"/>
																	<joint name="right_2tip1_joint" type="hinge" pos="4.122874637245183e-17 -2.326417038471834e-19 3.717020785801755e-17" range="-0.5235990285873413 0.5235990285873413" axis="0.0 0.0 1.0"/>
																	<body name="right_2tip2" pos="0.0 5.551115123125783e-17 0.0" quat="0.7071090340614319 0.7071045637130737 -4.906461508027686e-18 -3.9251940218405255e-17">
																		<inertial mass="0.06310640275478363" pos="0.04163796454668045 -0.0016735829412937164 -0.0008487995364703238" quat="0.7089323997497559 -0.7050620913505554 0.016155026853084564 -0.006425212137401104" diaginertia="1.090284604288172e-05 0.0001451448624720797 0.00014662386092823"/>
																		<geom name="SM_right_2tip2_collision_0" type="mesh" pos="0.0 0.0 0.0" quat="1.0 0.0 0.0 0.0" mesh="finger_phaprox" class="rollin-justin_collision"/>
																		<joint name="right_2tip2_joint" type="hinge" pos="4.122874637245183e-17 -2.326417038471834e-19 3.717020785801755e-17" range="-0.34906598925590515 1.500980019569397" axis="0.0 0.0 1.0"/>
																		<body name="right_2tip3" pos="0.07500000298023224 2.220446049250313e-16 5.551115123125783e-17" quat="1.0 6.071532165918825e-18 5.204170427930421e-18 1.3877787807814457e-17">
																			<inertial mass="0.02652239054441452" pos="0.019823182374238968 -0.0014702541520819068 0.0006521216128021479" quat="0.7099600434303284 -0.7039279937744141 0.006069484166800976 -0.020131085067987442" diaginertia="4.763823199027684e-06 1.7667940483079292e-05 1.8650636775419116e-05"/>
																			<geom name="SM_right_2tip3_collision_0" type="mesh" pos="0.0 0.0 0.0" quat="1.0 0.0 0.0 0.0" mesh="finger_phamed" class="rollin-justin_collision"/>
																			<joint name="right_2tip3_joint" type="hinge" pos="2.0004116387975734e-16 1.1363497558832154e-16 -6.240647058398474e-16" range="-0.17453299462795258 1.7627800703048706" axis="0.0 0.0 1.0"/>
																			<body name="right_2tip4" pos="0.03999999910593033 0.0 0.0" quat="0.7071090340614319 4.051696407279485e-17 3.549565349979785e-17 -0.7071045637130737">
																				<inertial mass="0.02797284722328186" pos="-0.002071711700409651 0.02310049533843994 0.000411754910601303" quat="0.44483330845832825 0.4916505813598633 0.5386422872543335 0.5198726058006287" diaginertia="2.3384186533803586e-06 1.9123144738841802e-05 1.9700763004948385e-05"/>
																				<geom name="SM_right_2tip4_collision_0" type="mesh" pos="0.0 0.0 0.0" quat="1.0 0.0 0.0 0.0" mesh="hii2_geh_phadist_gesamt_asm" class="rollin-justin_collision"/>
																				<joint name="right_2tip4_joint" type="hinge" pos="5.5005224407563244e-17 -5.805362650156002e-17 -4.720572319167747e-16" range="-0.17453299462795258 1.7627800703048706" axis="0.0 0.0 1.0"/>
																			</body>
																		</body>
																	</body>
																</body>
															</body>
															<body name="right_palm" pos="0.0 0.10109999775886536 -1.3877787807814457e-17" quat="9.381886343362567e-07 9.381827226206951e-07 0.7071045637130737 0.7071090340614319">
															</body>
														</body>
													</body>
												</body>
											</body>
										</body>
									</body>
								</body>
								<body name="head1" pos="0.23499999940395355 0.08799999952316284 -2.3985006589770017e-23" quat="0.5000031590461731 0.5 0.4999968409538269 0.5">
									<inertial mass="0.3457649350166321" pos="-1.4184065033617799e-09 1.788661441182171e-10 -0.012623847462236881" quat="0.7071066498756409 -0.00046674947952851653 -0.7071066498756409 -0.0004667480825446546" diaginertia="0.00031857428257353604 0.0029316958971321583 0.0029531477484852076"/>
									<geom name="SM_head1_collision_0" type="mesh" pos="0.0 0.0 0.054999999701976776" quat="1.0 0.0 0.0 0.0" mesh="head1" material="M_head1_collision_0" class="rollin-justin_collision"/>
									<joint name="head1_joint" type="hinge" pos="7.264003376279032e-22 1.1102239510674426e-16 1.38770855314744e-17" range="-0.785398006439209 0.785398006439209" axis="0.0 0.0 1.0"/>
									<body name="head2" pos="2.7755575615628914e-17 0.0 0.0" quat="0.7071090340614319 -0.7071045637130737 -2.994756567240617e-22 8.765023672926565e-22">
										<inertial mass="8.571846008300781" pos="0.037757113575935364 -0.15114359557628632 3.2431435670332576e-07" quat="0.7857056260108948 0.00014016576460562646 -0.00010021941125160083 -0.6186004877090454" diaginertia="0.04123464226722717 0.2622271478176117 0.2707614600658417"/>
										<geom name="SM_head2_collision_0" type="mesh" pos="0.0 0.0 0.0" quat="1.0 0.0 0.0 0.0" mesh="head2" material="M_head2_collision_0" class="rollin-justin_collision"/>
										<joint name="head2_joint" type="hinge" pos="-2.7755575615628914e-17 1.756038327595333e-22 1.1110059107113177e-27" range="-0.43633201718330383 0.785398006439209" axis="0.0 0.0 1.0"/>
									</body>
								</body>
							</body>
						</body>
					</body>
				</body>
			</body>
		</body>
	</worldbody>
	<equality>
		<joint name="right_3middle4_joint_right_3middle3_joint" joint1="right_3middle4_joint" joint2="right_3middle3_joint" polycoef="0.0 1.0 0.0 0.0 0.0"/>
		<joint name="right_2tip4_joint_right_2tip3_joint" joint1="right_2tip4_joint" joint2="right_2tip3_joint" polycoef="0.0 1.0 0.0 0.0 0.0"/>
		<joint name="left_2tip4_joint_left_2tip3_joint" joint1="left_2tip4_joint" joint2="left_2tip3_joint" polycoef="0.0 1.0 0.0 0.0 0.0"/>
		<joint name="left_4ring4_joint_left_4ring3_joint" joint1="left_4ring4_joint" joint2="left_4ring3_joint" polycoef="0.0 1.0 0.0 0.0 0.0"/>
		<joint name="right_4ring4_joint_right_4ring3_joint" joint1="right_4ring4_joint" joint2="right_4ring3_joint" polycoef="0.0 1.0 0.0 0.0 0.0"/>
		<joint name="left_1thumb4_joint_left_1thumb3_joint" joint1="left_1thumb4_joint" joint2="left_1thumb3_joint" polycoef="0.0 1.0 0.0 0.0 0.0"/>
		<joint name="right_1thumb4_joint_right_1thumb3_joint" joint1="right_1thumb4_joint" joint2="right_1thumb3_joint" polycoef="0.0 1.0 0.0 0.0 0.0"/>
		<joint name="left_3middle4_joint_left_3middle3_joint" joint1="left_3middle4_joint" joint2="left_3middle3_joint" polycoef="0.0 1.0 0.0 0.0 0.0"/>
	</equality>
	<contact>
		<exclude name="left_arm5_left_arm7" body1="left_arm5" body2="left_arm7" />
		<exclude name="left_1thumb2_left_arm7" body1="left_1thumb2" body2="left_arm7" />
		<exclude name="left_3middle2_left_arm7" body1="left_3middle2" body2="left_arm7" />
		<exclude name="left_4ring2_left_arm7" body1="left_4ring2" body2="left_arm7" />
		<exclude name="left_2tip2_left_arm7" body1="left_2tip2" body2="left_arm7" />
		<exclude name="left_3middle2_left_3middle_base" body1="left_3middle2" body2="left_3middle_base" />
		<exclude name="right_arm5_right_arm7" body1="right_arm5" body2="right_arm7" />
		<exclude name="right_1thumb2_right_arm7" body1="right_1thumb2" body2="right_arm7" />
		<exclude name="right_3middle2_right_arm7" body1="right_3middle2" body2="right_arm7" />
		<exclude name="right_4ring2_right_arm7" body1="right_4ring2" body2="right_arm7" />
		<exclude name="right_2tip2_right_arm7" body1="right_2tip2" body2="right_arm7" />
  	</contact>

	<actuator>
		<position name="head1_actuator" joint="head1_joint" kp="150" kv="10" inheritrange="1"/>
		<position name="head2_actuator" joint="head2_joint" kp="150" kv="10" inheritrange="1"/>
		<position name="torso1_actuator" joint="torso1_joint" kp="1500" kv="100" inheritrange="1"/>
		<position name="torso2_actuator" joint="torso2_joint" kp="1500" kv="100" inheritrange="1"/>
		<position name="torso3_actuator" joint="torso3_joint" kp="1500" kv="100" inheritrange="1"/>
		<position name="torso4_actuator" joint="torso4_joint" kp="1500" kv="100" inheritrange="1"/>
		<position name="left_arm1_actuator" joint="left_arm1_joint" kp="100" kv="10" inheritrange="1"/>
		<position name="left_arm2_actuator" joint="left_arm2_joint" kp="100" kv="10" inheritrange="1"/>
		<position name="left_arm3_actuator" joint="left_arm3_joint" kp="50" kv="5" inheritrange="1"/>
		<position name="left_arm4_actuator" joint="left_arm4_joint" kp="50" kv="5" inheritrange="1"/>
		<position name="left_arm5_actuator" joint="left_arm5_joint" kp="20" kv="2" inheritrange="1"/>
		<position name="left_arm6_actuator" joint="left_arm6_joint" kp="20" kv="2" inheritrange="1"/>
		<position name="left_arm7_actuator" joint="left_arm7_joint" kp="20" kv="2" inheritrange="1"/>
		<position name="right_arm1_actuator" joint="right_arm1_joint" kp="100" kv="10" inheritrange="1"/>
		<position name="right_arm2_actuator" joint="right_arm2_joint" kp="100" kv="10" inheritrange="1"/>
		<position name="right_arm3_actuator" joint="right_arm3_joint" kp="50" kv="5" inheritrange="1"/>
		<position name="right_arm4_actuator" joint="right_arm4_joint" kp="50" kv="5" inheritrange="1"/>
		<position name="right_arm5_actuator" joint="right_arm5_joint" kp="20" kv="2" inheritrange="1"/>
		<position name="right_arm6_actuator" joint="right_arm6_joint" kp="20" kv="2" inheritrange="1"/>
		<position name="right_arm7_actuator" joint="right_arm7_joint" kp="20" kv="2" inheritrange="1"/>

		<position name="left_1thumb1_actuator" joint="left_1thumb1_joint" kp="2" kv="0.2" inheritrange="1"/>
		<position name="left_1thumb2_actuator" joint="left_1thumb2_joint" kp="2" kv="0.2" inheritrange="1"/>
		<position name="left_1thumb3_actuator" joint="left_1thumb3_joint" kp="0.5" kv="0.05" inheritrange="1"/>
		<position name="left_1thumb4_actuator" joint="left_1thumb4_joint" kp="0.1" kv="0.01" inheritrange="1"/>
		<position name="left_2tip1_actuator" joint="left_2tip1_joint" kp="2" kv="0.2" inheritrange="1"/>
		<position name="left_2tip2_actuator" joint="left_2tip2_joint" kp="2" kv="0.2" inheritrange="1"/>
		<position name="left_2tip3_actuator" joint="left_2tip3_joint" kp="0.5" kv="0.05" inheritrange="1"/>
		<position name="left_2tip4_actuator" joint="left_2tip4_joint" kp="0.1" kv="0.01" inheritrange="1"/>
		<position name="left_3middle1_actuator" joint="left_3middle1_joint" kp="2" kv="0.2" inheritrange="1"/>
		<position name="left_3middle2_actuator" joint="left_3middle2_joint" kp="2" kv="0.2" inheritrange="1"/>
		<position name="left_3middle3_actuator" joint="left_3middle3_joint" kp="0.5" kv="0.05" inheritrange="1"/>
		<position name="left_3middle4_actuator" joint="left_3middle4_joint" kp="0.1" kv="0.01" inheritrange="1"/>
		<position name="left_4ring1_actuator" joint="left_4ring1_joint" kp="2" kv="0.2" inheritrange="1"/>
		<position name="left_4ring2_actuator" joint="left_4ring2_joint" kp="2" kv="0.2" inheritrange="1"/>
		<position name="left_4ring3_actuator" joint="left_4ring3_joint" kp="0.5" kv="0.05" inheritrange="1"/>
		<position name="left_4ring4_actuator" joint="left_4ring4_joint" kp="0.1" kv="0.01" inheritrange="1"/>
		<position name="right_1thumb1_actuator" joint="right_1thumb1_joint" kp="2" kv="0.2" inheritrange="1"/>
		<position name="right_1thumb2_actuator" joint="right_1thumb2_joint" kp="2" kv="0.2" inheritrange="1"/>
		<position name="right_1thumb3_actuator" joint="right_1thumb3_joint" kp="0.5" kv="0.05" inheritrange="1"/>
		<position name="right_1thumb4_actuator" joint="right_1thumb4_joint" kp="0.1" kv="0.01" inheritrange="1"/>
		<position name="right_2tip1_actuator" joint="right_2tip1_joint" kp="2" kv="0.2" inheritrange="1"/>
		<position name="right_2tip2_actuator" joint="right_2tip2_joint" kp="2" kv="0.2" inheritrange="1"/>
		<position name="right_2tip3_actuator" joint="right_2tip3_joint" kp="0.5" kv="0.05" inheritrange="1"/>
		<position name="right_2tip4_actuator" joint="right_2tip4_joint" kp="0.1" kv="0.01" inheritrange="1"/>
		<position name="right_3middle1_actuator" joint="right_3middle1_joint" kp="2" kv="0.2" inheritrange="1"/>
		<position name="right_3middle2_actuator" joint="right_3middle2_joint" kp="2" kv="0.2" inheritrange="1"/>
		<position name="right_3middle3_actuator" joint="right_3middle3_joint" kp="0.5" kv="0.05" inheritrange="1"/>
		<position name="right_3middle4_actuator" joint="right_3middle4_joint" kp="0.1" kv="0.01" inheritrange="1"/>
		<position name="right_4ring1_actuator" joint="right_4ring1_joint" kp="2" kv="0.2" inheritrange="1"/>
		<position name="right_4ring2_actuator" joint="right_4ring2_joint" kp="2" kv="0.2" inheritrange="1"/>
		<position name="right_4ring3_actuator" joint="right_4ring3_joint" kp="0.5" kv="0.05" inheritrange="1"/>
		<position name="right_4ring4_actuator" joint="right_4ring4_joint" kp="0.1" kv="0.01" inheritrange="1"/>
	</actuator>

</mujoco>
