<mujoco model="liquid">
  <compiler angle="radian"/>

  <worldbody>
    <body name="liquid">
      <body name="B0_0_0" pos="-0.0065 -0.0065 -0.0525">
        <joint name="B0_0_0_0_0" pos="0 0 0" axis="1 0 0" type="slide" group="3"/>
        <joint name="B0_0_0_0_1" pos="0 0 0" axis="0 1 0" type="slide" group="3"/>
        <joint name="B0_0_0_0_2" pos="0 0 0" axis="0 0 1" type="slide" group="3"/>
        <geom size="0.007" condim="1" priority="1" rgba="0.8 0.2 0.1 1"/>
        <site name="S0" pos="0 0 0" group="3"/>
      </body>
      <body name="B0_0_1" pos="-0.0065 -0.0065 -0.0375">
        <joint name="B0_0_0_1_0" pos="0 0 0" axis="1 0 0" type="slide" group="3"/>
        <joint name="B0_0_0_1_1" pos="0 0 0" axis="0 1 0" type="slide" group="3"/>
        <joint name="B0_0_0_1_2" pos="0 0 0" axis="0 0 1" type="slide" group="3"/>
        <geom size="0.007" condim="1" priority="1" rgba="0.8 0.2 0.1 1"/>
        <site name="S1" pos="0 0 0" group="3"/>
      </body>
      <body name="B0_0_2" pos="-0.0065 -0.0065 -0.0225">
        <joint name="B0_0_0_2_0" pos="0 0 0" axis="1 0 0" type="slide" group="3"/>
        <joint name="B0_0_0_2_1" pos="0 0 0" axis="0 1 0" type="slide" group="3"/>
        <joint name="B0_0_0_2_2" pos="0 0 0" axis="0 0 1" type="slide" group="3"/>
        <geom size="0.007" condim="1" priority="1" rgba="0.8 0.2 0.1 1"/>
        <site name="S2" pos="0 0 0" group="3"/>
      </body>
      <body name="B0_0_3" pos="-0.0065 -0.0065 -0.0075">
        <joint name="B0_0_0_3_0" pos="0 0 0" axis="1 0 0" type="slide" group="3"/>
        <joint name="B0_0_0_3_1" pos="0 0 0" axis="0 1 0" type="slide" group="3"/>
        <joint name="B0_0_0_3_2" pos="0 0 0" axis="0 0 1" type="slide" group="3"/>
        <geom size="0.007" condim="1" priority="1" rgba="0.8 0.2 0.1 1"/>
        <site name="S3" pos="0 0 0" group="3"/>
      </body>
      <body name="B0_0_4" pos="-0.0065 -0.0065 0.0075">
        <joint name="B0_0_0_4_0" pos="0 0 0" axis="1 0 0" type="slide" group="3"/>
        <joint name="B0_0_0_4_1" pos="0 0 0" axis="0 1 0" type="slide" group="3"/>
        <joint name="B0_0_0_4_2" pos="0 0 0" axis="0 0 1" type="slide" group="3"/>
        <geom size="0.007" condim="1" priority="1" rgba="0.8 0.2 0.1 1"/>
        <site name="S4" pos="0 0 0" group="3"/>
      </body>
      <body name="B0_0_5" pos="-0.0065 -0.0065 0.0225">
        <joint name="B0_0_0_5_0" pos="0 0 0" axis="1 0 0" type="slide" group="3"/>
        <joint name="B0_0_0_5_1" pos="0 0 0" axis="0 1 0" type="slide" group="3"/>
        <joint name="B0_0_0_5_2" pos="0 0 0" axis="0 0 1" type="slide" group="3"/>
        <geom size="0.007" condim="1" priority="1" rgba="0.8 0.2 0.1 1"/>
        <site name="S5" pos="0 0 0" group="3"/>
      </body>
      <body name="B0_0_6" pos="-0.0065 -0.0065 0.0375">
        <joint name="B0_0_0_6_0" pos="0 0 0" axis="1 0 0" type="slide" group="3"/>
        <joint name="B0_0_0_6_1" pos="0 0 0" axis="0 1 0" type="slide" group="3"/>
        <joint name="B0_0_0_6_2" pos="0 0 0" axis="0 0 1" type="slide" group="3"/>
        <geom size="0.007" condim="1" priority="1" rgba="0.8 0.2 0.1 1"/>
        <site name="S6" pos="0 0 0" group="3"/>
      </body>
      <body name="B0_1_0" pos="-0.0065 0.0085 -0.0525">
        <joint name="B0_0_1_0_0" pos="0 0 0" axis="1 0 0" type="slide" group="3"/>
        <joint name="B0_0_1_0_1" pos="0 0 0" axis="0 1 0" type="slide" group="3"/>
        <joint name="B0_0_1_0_2" pos="0 0 0" axis="0 0 1" type="slide" group="3"/>
        <geom size="0.007" condim="1" priority="1" rgba="0.8 0.2 0.1 1"/>
        <site name="S7" pos="0 0 0" group="3"/>
      </body>
      <body name="B0_1_1" pos="-0.0065 0.0085 -0.0375">
        <joint name="B0_0_1_1_0" pos="0 0 0" axis="1 0 0" type="slide" group="3"/>
        <joint name="B0_0_1_1_1" pos="0 0 0" axis="0 1 0" type="slide" group="3"/>
        <joint name="B0_0_1_1_2" pos="0 0 0" axis="0 0 1" type="slide" group="3"/>
        <geom size="0.007" condim="1" priority="1" rgba="0.8 0.2 0.1 1"/>
        <site name="S8" pos="0 0 0" group="3"/>
      </body>
      <body name="B0_1_2" pos="-0.0065 0.0085 -0.0225">
        <joint name="B0_0_1_2_0" pos="0 0 0" axis="1 0 0" type="slide" group="3"/>
        <joint name="B0_0_1_2_1" pos="0 0 0" axis="0 1 0" type="slide" group="3"/>
        <joint name="B0_0_1_2_2" pos="0 0 0" axis="0 0 1" type="slide" group="3"/>
        <geom size="0.007" condim="1" priority="1" rgba="0.8 0.2 0.1 1"/>
        <site name="S9" pos="0 0 0" group="3"/>
      </body>
      <body name="B0_1_3" pos="-0.0065 0.0085 -0.0075">
        <joint name="B0_0_1_3_0" pos="0 0 0" axis="1 0 0" type="slide" group="3"/>
        <joint name="B0_0_1_3_1" pos="0 0 0" axis="0 1 0" type="slide" group="3"/>
        <joint name="B0_0_1_3_2" pos="0 0 0" axis="0 0 1" type="slide" group="3"/>
        <geom size="0.007" condim="1" priority="1" rgba="0.8 0.2 0.1 1"/>
        <site name="S10" pos="0 0 0" group="3"/>
      </body>
      <body name="B0_1_4" pos="-0.0065 0.0085 0.0075">
        <joint name="B0_0_1_4_0" pos="0 0 0" axis="1 0 0" type="slide" group="3"/>
        <joint name="B0_0_1_4_1" pos="0 0 0" axis="0 1 0" type="slide" group="3"/>
        <joint name="B0_0_1_4_2" pos="0 0 0" axis="0 0 1" type="slide" group="3"/>
        <geom size="0.007" condim="1" priority="1" rgba="0.8 0.2 0.1 1"/>
        <site name="S11" pos="0 0 0" group="3"/>
      </body>
      <body name="B0_1_5" pos="-0.0065 0.0085 0.0225">
        <joint name="B0_0_1_5_0" pos="0 0 0" axis="1 0 0" type="slide" group="3"/>
        <joint name="B0_0_1_5_1" pos="0 0 0" axis="0 1 0" type="slide" group="3"/>
        <joint name="B0_0_1_5_2" pos="0 0 0" axis="0 0 1" type="slide" group="3"/>
        <geom size="0.007" condim="1" priority="1" rgba="0.8 0.2 0.1 1"/>
        <site name="S12" pos="0 0 0" group="3"/>
      </body>
      <body name="B0_1_6" pos="-0.0065 0.0085 0.0375">
        <joint name="B0_0_1_6_0" pos="0 0 0" axis="1 0 0" type="slide" group="3"/>
        <joint name="B0_0_1_6_1" pos="0 0 0" axis="0 1 0" type="slide" group="3"/>
        <joint name="B0_0_1_6_2" pos="0 0 0" axis="0 0 1" type="slide" group="3"/>
        <geom size="0.007" condim="1" priority="1" rgba="0.8 0.2 0.1 1"/>
        <site name="S13" pos="0 0 0" group="3"/>
      </body>
      <body name="B1_0_0" pos="0.0085 -0.0065 -0.0525">
        <joint name="B0_1_0_0_0" pos="0 0 0" axis="1 0 0" type="slide" group="3"/>
        <joint name="B0_1_0_0_1" pos="0 0 0" axis="0 1 0" type="slide" group="3"/>
        <joint name="B0_1_0_0_2" pos="0 0 0" axis="0 0 1" type="slide" group="3"/>
        <geom size="0.007" condim="1" priority="1" rgba="0.8 0.2 0.1 1"/>
        <site name="S14" pos="0 0 0" group="3"/>
      </body>
      <body name="B1_0_1" pos="0.0085 -0.0065 -0.0375">
        <joint name="B0_1_0_1_0" pos="0 0 0" axis="1 0 0" type="slide" group="3"/>
        <joint name="B0_1_0_1_1" pos="0 0 0" axis="0 1 0" type="slide" group="3"/>
        <joint name="B0_1_0_1_2" pos="0 0 0" axis="0 0 1" type="slide" group="3"/>
        <geom size="0.007" condim="1" priority="1" rgba="0.8 0.2 0.1 1"/>
        <site name="S15" pos="0 0 0" group="3"/>
      </body>
      <body name="B1_0_2" pos="0.0085 -0.0065 -0.0225">
        <joint name="B0_1_0_2_0" pos="0 0 0" axis="1 0 0" type="slide" group="3"/>
        <joint name="B0_1_0_2_1" pos="0 0 0" axis="0 1 0" type="slide" group="3"/>
        <joint name="B0_1_0_2_2" pos="0 0 0" axis="0 0 1" type="slide" group="3"/>
        <geom size="0.007" condim="1" priority="1" rgba="0.8 0.2 0.1 1"/>
        <site name="S16" pos="0 0 0" group="3"/>
      </body>
      <body name="B1_0_3" pos="0.0085 -0.0065 -0.0075">
        <joint name="B0_1_0_3_0" pos="0 0 0" axis="1 0 0" type="slide" group="3"/>
        <joint name="B0_1_0_3_1" pos="0 0 0" axis="0 1 0" type="slide" group="3"/>
        <joint name="B0_1_0_3_2" pos="0 0 0" axis="0 0 1" type="slide" group="3"/>
        <geom size="0.007" condim="1" priority="1" rgba="0.8 0.2 0.1 1"/>
        <site name="S17" pos="0 0 0" group="3"/>
      </body>
      <body name="B1_0_4" pos="0.0085 -0.0065 0.0075">
        <joint name="B0_1_0_4_0" pos="0 0 0" axis="1 0 0" type="slide" group="3"/>
        <joint name="B0_1_0_4_1" pos="0 0 0" axis="0 1 0" type="slide" group="3"/>
        <joint name="B0_1_0_4_2" pos="0 0 0" axis="0 0 1" type="slide" group="3"/>
        <geom size="0.007" condim="1" priority="1" rgba="0.8 0.2 0.1 1"/>
        <site name="S18" pos="0 0 0" group="3"/>
      </body>
      <body name="B1_0_5" pos="0.0085 -0.0065 0.0225">
        <joint name="B0_1_0_5_0" pos="0 0 0" axis="1 0 0" type="slide" group="3"/>
        <joint name="B0_1_0_5_1" pos="0 0 0" axis="0 1 0" type="slide" group="3"/>
        <joint name="B0_1_0_5_2" pos="0 0 0" axis="0 0 1" type="slide" group="3"/>
        <geom size="0.007" condim="1" priority="1" rgba="0.8 0.2 0.1 1"/>
        <site name="S19" pos="0 0 0" group="3"/>
      </body>
      <body name="B1_0_6" pos="0.0085 -0.0065 0.0375">
        <joint name="B0_1_0_6_0" pos="0 0 0" axis="1 0 0" type="slide" group="3"/>
        <joint name="B0_1_0_6_1" pos="0 0 0" axis="0 1 0" type="slide" group="3"/>
        <joint name="B0_1_0_6_2" pos="0 0 0" axis="0 0 1" type="slide" group="3"/>
        <geom size="0.007" condim="1" priority="1" rgba="0.8 0.2 0.1 1"/>
        <site name="S20" pos="0 0 0" group="3"/>
      </body>
      <body name="B1_1_0" pos="0.0085 0.0085 -0.0525">
        <joint name="B0_1_1_0_0" pos="0 0 0" axis="1 0 0" type="slide" group="3"/>
        <joint name="B0_1_1_0_1" pos="0 0 0" axis="0 1 0" type="slide" group="3"/>
        <joint name="B0_1_1_0_2" pos="0 0 0" axis="0 0 1" type="slide" group="3"/>
        <geom size="0.007" condim="1" priority="1" rgba="0.8 0.2 0.1 1"/>
        <site name="S21" pos="0 0 0" group="3"/>
      </body>
      <body name="B1_1_1" pos="0.0085 0.0085 -0.0375">
        <joint name="B0_1_1_1_0" pos="0 0 0" axis="1 0 0" type="slide" group="3"/>
        <joint name="B0_1_1_1_1" pos="0 0 0" axis="0 1 0" type="slide" group="3"/>
        <joint name="B0_1_1_1_2" pos="0 0 0" axis="0 0 1" type="slide" group="3"/>
        <geom size="0.007" condim="1" priority="1" rgba="0.8 0.2 0.1 1"/>
        <site name="S22" pos="0 0 0" group="3"/>
      </body>
      <body name="B1_1_2" pos="0.0085 0.0085 -0.0225">
        <joint name="B0_1_1_2_0" pos="0 0 0" axis="1 0 0" type="slide" group="3"/>
        <joint name="B0_1_1_2_1" pos="0 0 0" axis="0 1 0" type="slide" group="3"/>
        <joint name="B0_1_1_2_2" pos="0 0 0" axis="0 0 1" type="slide" group="3"/>
        <geom size="0.007" condim="1" priority="1" rgba="0.8 0.2 0.1 1"/>
        <site name="S23" pos="0 0 0" group="3"/>
      </body>
      <body name="B1_1_3" pos="0.0085 0.0085 -0.0075">
        <joint name="B0_1_1_3_0" pos="0 0 0" axis="1 0 0" type="slide" group="3"/>
        <joint name="B0_1_1_3_1" pos="0 0 0" axis="0 1 0" type="slide" group="3"/>
        <joint name="B0_1_1_3_2" pos="0 0 0" axis="0 0 1" type="slide" group="3"/>
        <geom size="0.007" condim="1" priority="1" rgba="0.8 0.2 0.1 1"/>
        <site name="S24" pos="0 0 0" group="3"/>
      </body>
      <body name="B1_1_4" pos="0.0085 0.0085 0.0075">
        <joint name="B0_1_1_4_0" pos="0 0 0" axis="1 0 0" type="slide" group="3"/>
        <joint name="B0_1_1_4_1" pos="0 0 0" axis="0 1 0" type="slide" group="3"/>
        <joint name="B0_1_1_4_2" pos="0 0 0" axis="0 0 1" type="slide" group="3"/>
        <geom size="0.007" condim="1" priority="1" rgba="0.8 0.2 0.1 1"/>
        <site name="S25" pos="0 0 0" group="3"/>
      </body>
      <body name="B1_1_5" pos="0.0085 0.0085 0.0225">
        <joint name="B0_1_1_5_0" pos="0 0 0" axis="1 0 0" type="slide" group="3"/>
        <joint name="B0_1_1_5_1" pos="0 0 0" axis="0 1 0" type="slide" group="3"/>
        <joint name="B0_1_1_5_2" pos="0 0 0" axis="0 0 1" type="slide" group="3"/>
        <geom size="0.007" condim="1" priority="1" rgba="0.8 0.2 0.1 1"/>
        <site name="S26" pos="0 0 0" group="3"/>
      </body>
      <body name="B1_1_6" pos="0.0085 0.0085 0.0375">
        <joint name="B0_1_1_6_0" pos="0 0 0" axis="1 0 0" type="slide" group="3"/>
        <joint name="B0_1_1_6_1" pos="0 0 0" axis="0 1 0" type="slide" group="3"/>
        <joint name="B0_1_1_6_2" pos="0 0 0" axis="0 0 1" type="slide" group="3"/>
        <geom size="0.007" condim="1" priority="1" rgba="0.8 0.2 0.1 1"/>
        <site name="S27" pos="0 0 0" group="3"/>
      </body>
    </body>
  </worldbody>
</mujoco>
